<?xml version="1.0" encoding="UTF-8"?>
<testng-results retried="6" ignored="0" total="9" passed="1" failed="2" skipped="0">
  <reporter-output>
  </reporter-output>
  <suite started-at="2024-08-27T14:37:11 IST" name="Suite" finished-at="2024-08-27T14:37:11 IST" duration-ms="144">
    <groups>
    </groups>
    <test started-at="2024-08-27T14:37:11 IST" name="Test" finished-at="2024-08-27T14:37:11 IST" duration-ms="144">
      <class name="TestNgExecuteFailedTestCases.FailedTestCaseExample">
        <test-method retried="true" signature="TestCase01()[pri:0, instance:TestNgExecuteFailedTestCases.FailedTestCaseExample@70e9c95d]" started-at="2024-08-27T14:37:11 IST" name="TestCase01" finished-at="2024-08-27T14:37:11 IST" duration-ms="23" status="SKIP">
          <exception class="java.lang.AssertionError">
            <message>
              <![CDATA[expected [true] but found [false]]]>
            </message>
            <full-stacktrace>
              <![CDATA[java.lang.AssertionError: expected [true] but found [false]
at org.testng.Assert.fail(Assert.java:110)
at org.testng.Assert.failNotEquals(Assert.java:1413)
at org.testng.Assert.assertTrue(Assert.java:56)
at org.testng.Assert.assertTrue(Assert.java:66)
at TestNgExecuteFailedTestCases.FailedTestCaseExample.TestCase01(FailedTestCaseExample.java:8)
at java.base/jdk.internal.reflect.DirectMethodHandleAccessor.invoke(DirectMethodHandleAccessor.java:103)
at java.base/java.lang.reflect.Method.invoke(Method.java:580)
at org.testng.internal.invokers.MethodInvocationHelper.invokeMethod(MethodInvocationHelper.java:139)
at org.testng.internal.invokers.TestInvoker.invokeMethod(TestInvoker.java:677)
at org.testng.internal.invokers.TestInvoker.invokeTestMethod(TestInvoker.java:221)
at org.testng.internal.invokers.MethodRunner.runInSequence(MethodRunner.java:50)
at org.testng.internal.invokers.TestInvoker$MethodInvocationAgent.invoke(TestInvoker.java:962)
at org.testng.internal.invokers.TestInvoker.invokeTestMethods(TestInvoker.java:194)
at org.testng.internal.invokers.TestMethodWorker.invokeTestMethods(TestMethodWorker.java:148)
at org.testng.internal.invokers.TestMethodWorker.run(TestMethodWorker.java:128)
at java.base/java.util.ArrayList.forEach(ArrayList.java:1597)
at org.testng.TestRunner.privateRun(TestRunner.java:806)
at org.testng.TestRunner.run(TestRunner.java:601)
at org.testng.SuiteRunner.runTest(SuiteRunner.java:433)
at org.testng.SuiteRunner.runSequentially(SuiteRunner.java:427)
at org.testng.SuiteRunner.privateRun(SuiteRunner.java:387)
at org.testng.SuiteRunner.run(SuiteRunner.java:330)
at org.testng.SuiteRunnerWorker.runSuite(SuiteRunnerWorker.java:52)
at org.testng.SuiteRunnerWorker.run(SuiteRunnerWorker.java:95)
at org.testng.TestNG.runSuitesSequentially(TestNG.java:1256)
at org.testng.TestNG.runSuitesLocally(TestNG.java:1176)
at org.testng.TestNG.runSuites(TestNG.java:1099)
at org.testng.TestNG.run(TestNG.java:1067)
at org.testng.remote.AbstractRemoteTestNG.run(AbstractRemoteTestNG.java:115)
at org.testng.remote.RemoteTestNG.initAndRun(RemoteTestNG.java:293)
at org.testng.remote.RemoteTestNG.main(RemoteTestNG.java:91)
]]>
            </full-stacktrace>
          </exception> <!-- java.lang.AssertionError -->
          <reporter-output>
          </reporter-output>
        </test-method> <!-- TestCase01 -->
        <test-method retried="true" signature="TestCase01()[pri:0, instance:TestNgExecuteFailedTestCases.FailedTestCaseExample@70e9c95d]" started-at="2024-08-27T14:37:11 IST" name="TestCase01" finished-at="2024-08-27T14:37:11 IST" duration-ms="1" status="SKIP">
          <exception class="java.lang.AssertionError">
            <message>
              <![CDATA[expected [true] but found [false]]]>
            </message>
            <full-stacktrace>
              <![CDATA[java.lang.AssertionError: expected [true] but found [false]
at org.testng.Assert.fail(Assert.java:110)
at org.testng.Assert.failNotEquals(Assert.java:1413)
at org.testng.Assert.assertTrue(Assert.java:56)
at org.testng.Assert.assertTrue(Assert.java:66)
at TestNgExecuteFailedTestCases.FailedTestCaseExample.TestCase01(FailedTestCaseExample.java:8)
at java.base/jdk.internal.reflect.DirectMethodHandleAccessor.invoke(DirectMethodHandleAccessor.java:103)
at java.base/java.lang.reflect.Method.invoke(Method.java:580)
at org.testng.internal.invokers.MethodInvocationHelper.invokeMethod(MethodInvocationHelper.java:139)
at org.testng.internal.invokers.TestInvoker.invokeMethod(TestInvoker.java:677)
at org.testng.internal.invokers.TestInvoker.retryFailed(TestInvoker.java:263)
at org.testng.internal.invokers.MethodRunner.runInSequence(MethodRunner.java:62)
at org.testng.internal.invokers.TestInvoker$MethodInvocationAgent.invoke(TestInvoker.java:962)
at org.testng.internal.invokers.TestInvoker.invokeTestMethods(TestInvoker.java:194)
at org.testng.internal.invokers.TestMethodWorker.invokeTestMethods(TestMethodWorker.java:148)
at org.testng.internal.invokers.TestMethodWorker.run(TestMethodWorker.java:128)
at java.base/java.util.ArrayList.forEach(ArrayList.java:1597)
at org.testng.TestRunner.privateRun(TestRunner.java:806)
at org.testng.TestRunner.run(TestRunner.java:601)
at org.testng.SuiteRunner.runTest(SuiteRunner.java:433)
at org.testng.SuiteRunner.runSequentially(SuiteRunner.java:427)
at org.testng.SuiteRunner.privateRun(SuiteRunner.java:387)
at org.testng.SuiteRunner.run(SuiteRunner.java:330)
at org.testng.SuiteRunnerWorker.runSuite(SuiteRunnerWorker.java:52)
at org.testng.SuiteRunnerWorker.run(SuiteRunnerWorker.java:95)
at org.testng.TestNG.runSuitesSequentially(TestNG.java:1256)
at org.testng.TestNG.runSuitesLocally(TestNG.java:1176)
at org.testng.TestNG.runSuites(TestNG.java:1099)
at org.testng.TestNG.run(TestNG.java:1067)
at org.testng.remote.AbstractRemoteTestNG.run(AbstractRemoteTestNG.java:115)
at org.testng.remote.RemoteTestNG.initAndRun(RemoteTestNG.java:293)
at org.testng.remote.RemoteTestNG.main(RemoteTestNG.java:91)
]]>
            </full-stacktrace>
          </exception> <!-- java.lang.AssertionError -->
          <reporter-output>
          </reporter-output>
        </test-method> <!-- TestCase01 -->
        <test-method retried="true" signature="TestCase01()[pri:0, instance:TestNgExecuteFailedTestCases.FailedTestCaseExample@70e9c95d]" started-at="2024-08-27T14:37:11 IST" name="TestCase01" finished-at="2024-08-27T14:37:11 IST" duration-ms="2" status="SKIP">
          <exception class="java.lang.AssertionError">
            <message>
              <![CDATA[expected [true] but found [false]]]>
            </message>
            <full-stacktrace>
              <![CDATA[java.lang.AssertionError: expected [true] but found [false]
at org.testng.Assert.fail(Assert.java:110)
at org.testng.Assert.failNotEquals(Assert.java:1413)
at org.testng.Assert.assertTrue(Assert.java:56)
at org.testng.Assert.assertTrue(Assert.java:66)
at TestNgExecuteFailedTestCases.FailedTestCaseExample.TestCase01(FailedTestCaseExample.java:8)
at java.base/jdk.internal.reflect.DirectMethodHandleAccessor.invoke(DirectMethodHandleAccessor.java:103)
at java.base/java.lang.reflect.Method.invoke(Method.java:580)
at org.testng.internal.invokers.MethodInvocationHelper.invokeMethod(MethodInvocationHelper.java:139)
at org.testng.internal.invokers.TestInvoker.invokeMethod(TestInvoker.java:677)
at org.testng.internal.invokers.TestInvoker.retryFailed(TestInvoker.java:263)
at org.testng.internal.invokers.MethodRunner.runInSequence(MethodRunner.java:62)
at org.testng.internal.invokers.TestInvoker$MethodInvocationAgent.invoke(TestInvoker.java:962)
at org.testng.internal.invokers.TestInvoker.invokeTestMethods(TestInvoker.java:194)
at org.testng.internal.invokers.TestMethodWorker.invokeTestMethods(TestMethodWorker.java:148)
at org.testng.internal.invokers.TestMethodWorker.run(TestMethodWorker.java:128)
at java.base/java.util.ArrayList.forEach(ArrayList.java:1597)
at org.testng.TestRunner.privateRun(TestRunner.java:806)
at org.testng.TestRunner.run(TestRunner.java:601)
at org.testng.SuiteRunner.runTest(SuiteRunner.java:433)
at org.testng.SuiteRunner.runSequentially(SuiteRunner.java:427)
at org.testng.SuiteRunner.privateRun(SuiteRunner.java:387)
at org.testng.SuiteRunner.run(SuiteRunner.java:330)
at org.testng.SuiteRunnerWorker.runSuite(SuiteRunnerWorker.java:52)
at org.testng.SuiteRunnerWorker.run(SuiteRunnerWorker.java:95)
at org.testng.TestNG.runSuitesSequentially(TestNG.java:1256)
at org.testng.TestNG.runSuitesLocally(TestNG.java:1176)
at org.testng.TestNG.runSuites(TestNG.java:1099)
at org.testng.TestNG.run(TestNG.java:1067)
at org.testng.remote.AbstractRemoteTestNG.run(AbstractRemoteTestNG.java:115)
at org.testng.remote.RemoteTestNG.initAndRun(RemoteTestNG.java:293)
at org.testng.remote.RemoteTestNG.main(RemoteTestNG.java:91)
]]>
            </full-stacktrace>
          </exception> <!-- java.lang.AssertionError -->
          <reporter-output>
          </reporter-output>
        </test-method> <!-- TestCase01 -->
        <test-method signature="TestCase01()[pri:0, instance:TestNgExecuteFailedTestCases.FailedTestCaseExample@70e9c95d]" started-at="2024-08-27T14:37:11 IST" name="TestCase01" finished-at="2024-08-27T14:37:11 IST" duration-ms="1" status="FAIL">
          <exception class="java.lang.AssertionError">
            <message>
              <![CDATA[expected [true] but found [false]]]>
            </message>
            <full-stacktrace>
              <![CDATA[java.lang.AssertionError: expected [true] but found [false]
at org.testng.Assert.fail(Assert.java:110)
at org.testng.Assert.failNotEquals(Assert.java:1413)
at org.testng.Assert.assertTrue(Assert.java:56)
at org.testng.Assert.assertTrue(Assert.java:66)
at TestNgExecuteFailedTestCases.FailedTestCaseExample.TestCase01(FailedTestCaseExample.java:8)
at java.base/jdk.internal.reflect.DirectMethodHandleAccessor.invoke(DirectMethodHandleAccessor.java:103)
at java.base/java.lang.reflect.Method.invoke(Method.java:580)
at org.testng.internal.invokers.MethodInvocationHelper.invokeMethod(MethodInvocationHelper.java:139)
at org.testng.internal.invokers.TestInvoker.invokeMethod(TestInvoker.java:677)
at org.testng.internal.invokers.TestInvoker.retryFailed(TestInvoker.java:263)
at org.testng.internal.invokers.MethodRunner.runInSequence(MethodRunner.java:62)
at org.testng.internal.invokers.TestInvoker$MethodInvocationAgent.invoke(TestInvoker.java:962)
at org.testng.internal.invokers.TestInvoker.invokeTestMethods(TestInvoker.java:194)
at org.testng.internal.invokers.TestMethodWorker.invokeTestMethods(TestMethodWorker.java:148)
at org.testng.internal.invokers.TestMethodWorker.run(TestMethodWorker.java:128)
at java.base/java.util.ArrayList.forEach(ArrayList.java:1597)
at org.testng.TestRunner.privateRun(TestRunner.java:806)
at org.testng.TestRunner.run(TestRunner.java:601)
at org.testng.SuiteRunner.runTest(SuiteRunner.java:433)
at org.testng.SuiteRunner.runSequentially(SuiteRunner.java:427)
at org.testng.SuiteRunner.privateRun(SuiteRunner.java:387)
at org.testng.SuiteRunner.run(SuiteRunner.java:330)
at org.testng.SuiteRunnerWorker.runSuite(SuiteRunnerWorker.java:52)
at org.testng.SuiteRunnerWorker.run(SuiteRunnerWorker.java:95)
at org.testng.TestNG.runSuitesSequentially(TestNG.java:1256)
at org.testng.TestNG.runSuitesLocally(TestNG.java:1176)
at org.testng.TestNG.runSuites(TestNG.java:1099)
at org.testng.TestNG.run(TestNG.java:1067)
at org.testng.remote.AbstractRemoteTestNG.run(AbstractRemoteTestNG.java:115)
at org.testng.remote.RemoteTestNG.initAndRun(RemoteTestNG.java:293)
at org.testng.remote.RemoteTestNG.main(RemoteTestNG.java:91)
]]>
            </full-stacktrace>
          </exception> <!-- java.lang.AssertionError -->
          <reporter-output>
          </reporter-output>
        </test-method> <!-- TestCase01 -->
        <test-method retried="true" signature="TestCase02()[pri:0, instance:TestNgExecuteFailedTestCases.FailedTestCaseExample@70e9c95d]" started-at="2024-08-27T14:37:11 IST" name="TestCase02" finished-at="2024-08-27T14:37:11 IST" duration-ms="2" status="SKIP">
          <exception class="java.lang.AssertionError">
            <message>
              <![CDATA[expected [true] but found [false]]]>
            </message>
            <full-stacktrace>
              <![CDATA[java.lang.AssertionError: expected [true] but found [false]
at org.testng.Assert.fail(Assert.java:110)
at org.testng.Assert.failNotEquals(Assert.java:1413)
at org.testng.Assert.assertTrue(Assert.java:56)
at org.testng.Assert.assertTrue(Assert.java:66)
at TestNgExecuteFailedTestCases.FailedTestCaseExample.TestCase02(FailedTestCaseExample.java:12)
at java.base/jdk.internal.reflect.DirectMethodHandleAccessor.invoke(DirectMethodHandleAccessor.java:103)
at java.base/java.lang.reflect.Method.invoke(Method.java:580)
at org.testng.internal.invokers.MethodInvocationHelper.invokeMethod(MethodInvocationHelper.java:139)
at org.testng.internal.invokers.TestInvoker.invokeMethod(TestInvoker.java:677)
at org.testng.internal.invokers.TestInvoker.invokeTestMethod(TestInvoker.java:221)
at org.testng.internal.invokers.MethodRunner.runInSequence(MethodRunner.java:50)
at org.testng.internal.invokers.TestInvoker$MethodInvocationAgent.invoke(TestInvoker.java:962)
at org.testng.internal.invokers.TestInvoker.invokeTestMethods(TestInvoker.java:194)
at org.testng.internal.invokers.TestMethodWorker.invokeTestMethods(TestMethodWorker.java:148)
at org.testng.internal.invokers.TestMethodWorker.run(TestMethodWorker.java:128)
at java.base/java.util.ArrayList.forEach(ArrayList.java:1597)
at org.testng.TestRunner.privateRun(TestRunner.java:806)
at org.testng.TestRunner.run(TestRunner.java:601)
at org.testng.SuiteRunner.runTest(SuiteRunner.java:433)
at org.testng.SuiteRunner.runSequentially(SuiteRunner.java:427)
at org.testng.SuiteRunner.privateRun(SuiteRunner.java:387)
at org.testng.SuiteRunner.run(SuiteRunner.java:330)
at org.testng.SuiteRunnerWorker.runSuite(SuiteRunnerWorker.java:52)
at org.testng.SuiteRunnerWorker.run(SuiteRunnerWorker.java:95)
at org.testng.TestNG.runSuitesSequentially(TestNG.java:1256)
at org.testng.TestNG.runSuitesLocally(TestNG.java:1176)
at org.testng.TestNG.runSuites(TestNG.java:1099)
at org.testng.TestNG.run(TestNG.java:1067)
at org.testng.remote.AbstractRemoteTestNG.run(AbstractRemoteTestNG.java:115)
at org.testng.remote.RemoteTestNG.initAndRun(RemoteTestNG.java:293)
at org.testng.remote.RemoteTestNG.main(RemoteTestNG.java:91)
]]>
            </full-stacktrace>
          </exception> <!-- java.lang.AssertionError -->
          <reporter-output>
          </reporter-output>
        </test-method> <!-- TestCase02 -->
        <test-method retried="true" signature="TestCase02()[pri:0, instance:TestNgExecuteFailedTestCases.FailedTestCaseExample@70e9c95d]" started-at="2024-08-27T14:37:11 IST" name="TestCase02" finished-at="2024-08-27T14:37:11 IST" duration-ms="1" status="SKIP">
          <exception class="java.lang.AssertionError">
            <message>
              <![CDATA[expected [true] but found [false]]]>
            </message>
            <full-stacktrace>
              <![CDATA[java.lang.AssertionError: expected [true] but found [false]
at org.testng.Assert.fail(Assert.java:110)
at org.testng.Assert.failNotEquals(Assert.java:1413)
at org.testng.Assert.assertTrue(Assert.java:56)
at org.testng.Assert.assertTrue(Assert.java:66)
at TestNgExecuteFailedTestCases.FailedTestCaseExample.TestCase02(FailedTestCaseExample.java:12)
at java.base/jdk.internal.reflect.DirectMethodHandleAccessor.invoke(DirectMethodHandleAccessor.java:103)
at java.base/java.lang.reflect.Method.invoke(Method.java:580)
at org.testng.internal.invokers.MethodInvocationHelper.invokeMethod(MethodInvocationHelper.java:139)
at org.testng.internal.invokers.TestInvoker.invokeMethod(TestInvoker.java:677)
at org.testng.internal.invokers.TestInvoker.retryFailed(TestInvoker.java:263)
at org.testng.internal.invokers.MethodRunner.runInSequence(MethodRunner.java:62)
at org.testng.internal.invokers.TestInvoker$MethodInvocationAgent.invoke(TestInvoker.java:962)
at org.testng.internal.invokers.TestInvoker.invokeTestMethods(TestInvoker.java:194)
at org.testng.internal.invokers.TestMethodWorker.invokeTestMethods(TestMethodWorker.java:148)
at org.testng.internal.invokers.TestMethodWorker.run(TestMethodWorker.java:128)
at java.base/java.util.ArrayList.forEach(ArrayList.java:1597)
at org.testng.TestRunner.privateRun(TestRunner.java:806)
at org.testng.TestRunner.run(TestRunner.java:601)
at org.testng.SuiteRunner.runTest(SuiteRunner.java:433)
at org.testng.SuiteRunner.runSequentially(SuiteRunner.java:427)
at org.testng.SuiteRunner.privateRun(SuiteRunner.java:387)
at org.testng.SuiteRunner.run(SuiteRunner.java:330)
at org.testng.SuiteRunnerWorker.runSuite(SuiteRunnerWorker.java:52)
at org.testng.SuiteRunnerWorker.run(SuiteRunnerWorker.java:95)
at org.testng.TestNG.runSuitesSequentially(TestNG.java:1256)
at org.testng.TestNG.runSuitesLocally(TestNG.java:1176)
at org.testng.TestNG.runSuites(TestNG.java:1099)
at org.testng.TestNG.run(TestNG.java:1067)
at org.testng.remote.AbstractRemoteTestNG.run(AbstractRemoteTestNG.java:115)
at org.testng.remote.RemoteTestNG.initAndRun(RemoteTestNG.java:293)
at org.testng.remote.RemoteTestNG.main(RemoteTestNG.java:91)
]]>
            </full-stacktrace>
          </exception> <!-- java.lang.AssertionError -->
          <reporter-output>
          </reporter-output>
        </test-method> <!-- TestCase02 -->
        <test-method retried="true" signature="TestCase02()[pri:0, instance:TestNgExecuteFailedTestCases.FailedTestCaseExample@70e9c95d]" started-at="2024-08-27T14:37:11 IST" name="TestCase02" finished-at="2024-08-27T14:37:11 IST" duration-ms="2" status="SKIP">
          <exception class="java.lang.AssertionError">
            <message>
              <![CDATA[expected [true] but found [false]]]>
            </message>
            <full-stacktrace>
              <![CDATA[java.lang.AssertionError: expected [true] but found [false]
at org.testng.Assert.fail(Assert.java:110)
at org.testng.Assert.failNotEquals(Assert.java:1413)
at org.testng.Assert.assertTrue(Assert.java:56)
at org.testng.Assert.assertTrue(Assert.java:66)
at TestNgExecuteFailedTestCases.FailedTestCaseExample.TestCase02(FailedTestCaseExample.java:12)
at java.base/jdk.internal.reflect.DirectMethodHandleAccessor.invoke(DirectMethodHandleAccessor.java:103)
at java.base/java.lang.reflect.Method.invoke(Method.java:580)
at org.testng.internal.invokers.MethodInvocationHelper.invokeMethod(MethodInvocationHelper.java:139)
at org.testng.internal.invokers.TestInvoker.invokeMethod(TestInvoker.java:677)
at org.testng.internal.invokers.TestInvoker.retryFailed(TestInvoker.java:263)
at org.testng.internal.invokers.MethodRunner.runInSequence(MethodRunner.java:62)
at org.testng.internal.invokers.TestInvoker$MethodInvocationAgent.invoke(TestInvoker.java:962)
at org.testng.internal.invokers.TestInvoker.invokeTestMethods(TestInvoker.java:194)
at org.testng.internal.invokers.TestMethodWorker.invokeTestMethods(TestMethodWorker.java:148)
at org.testng.internal.invokers.TestMethodWorker.run(TestMethodWorker.java:128)
at java.base/java.util.ArrayList.forEach(ArrayList.java:1597)
at org.testng.TestRunner.privateRun(TestRunner.java:806)
at org.testng.TestRunner.run(TestRunner.java:601)
at org.testng.SuiteRunner.runTest(SuiteRunner.java:433)
at org.testng.SuiteRunner.runSequentially(SuiteRunner.java:427)
at org.testng.SuiteRunner.privateRun(SuiteRunner.java:387)
at org.testng.SuiteRunner.run(SuiteRunner.java:330)
at org.testng.SuiteRunnerWorker.runSuite(SuiteRunnerWorker.java:52)
at org.testng.SuiteRunnerWorker.run(SuiteRunnerWorker.java:95)
at org.testng.TestNG.runSuitesSequentially(TestNG.java:1256)
at org.testng.TestNG.runSuitesLocally(TestNG.java:1176)
at org.testng.TestNG.runSuites(TestNG.java:1099)
at org.testng.TestNG.run(TestNG.java:1067)
at org.testng.remote.AbstractRemoteTestNG.run(AbstractRemoteTestNG.java:115)
at org.testng.remote.RemoteTestNG.initAndRun(RemoteTestNG.java:293)
at org.testng.remote.RemoteTestNG.main(RemoteTestNG.java:91)
]]>
            </full-stacktrace>
          </exception> <!-- java.lang.AssertionError -->
          <reporter-output>
          </reporter-output>
        </test-method> <!-- TestCase02 -->
        <test-method signature="TestCase02()[pri:0, instance:TestNgExecuteFailedTestCases.FailedTestCaseExample@70e9c95d]" started-at="2024-08-27T14:37:11 IST" name="TestCase02" finished-at="2024-08-27T14:37:11 IST" duration-ms="2" status="FAIL">
          <exception class="java.lang.AssertionError">
            <message>
              <![CDATA[expected [true] but found [false]]]>
            </message>
            <full-stacktrace>
              <![CDATA[java.lang.AssertionError: expected [true] but found [false]
at org.testng.Assert.fail(Assert.java:110)
at org.testng.Assert.failNotEquals(Assert.java:1413)
at org.testng.Assert.assertTrue(Assert.java:56)
at org.testng.Assert.assertTrue(Assert.java:66)
at TestNgExecuteFailedTestCases.FailedTestCaseExample.TestCase02(FailedTestCaseExample.java:12)
at java.base/jdk.internal.reflect.DirectMethodHandleAccessor.invoke(DirectMethodHandleAccessor.java:103)
at java.base/java.lang.reflect.Method.invoke(Method.java:580)
at org.testng.internal.invokers.MethodInvocationHelper.invokeMethod(MethodInvocationHelper.java:139)
at org.testng.internal.invokers.TestInvoker.invokeMethod(TestInvoker.java:677)
at org.testng.internal.invokers.TestInvoker.retryFailed(TestInvoker.java:263)
at org.testng.internal.invokers.MethodRunner.runInSequence(MethodRunner.java:62)
at org.testng.internal.invokers.TestInvoker$MethodInvocationAgent.invoke(TestInvoker.java:962)
at org.testng.internal.invokers.TestInvoker.invokeTestMethods(TestInvoker.java:194)
at org.testng.internal.invokers.TestMethodWorker.invokeTestMethods(TestMethodWorker.java:148)
at org.testng.internal.invokers.TestMethodWorker.run(TestMethodWorker.java:128)
at java.base/java.util.ArrayList.forEach(ArrayList.java:1597)
at org.testng.TestRunner.privateRun(TestRunner.java:806)
at org.testng.TestRunner.run(TestRunner.java:601)
at org.testng.SuiteRunner.runTest(SuiteRunner.java:433)
at org.testng.SuiteRunner.runSequentially(SuiteRunner.java:427)
at org.testng.SuiteRunner.privateRun(SuiteRunner.java:387)
at org.testng.SuiteRunner.run(SuiteRunner.java:330)
at org.testng.SuiteRunnerWorker.runSuite(SuiteRunnerWorker.java:52)
at org.testng.SuiteRunnerWorker.run(SuiteRunnerWorker.java:95)
at org.testng.TestNG.runSuitesSequentially(TestNG.java:1256)
at org.testng.TestNG.runSuitesLocally(TestNG.java:1176)
at org.testng.TestNG.runSuites(TestNG.java:1099)
at org.testng.TestNG.run(TestNG.java:1067)
at org.testng.remote.AbstractRemoteTestNG.run(AbstractRemoteTestNG.java:115)
at org.testng.remote.RemoteTestNG.initAndRun(RemoteTestNG.java:293)
at org.testng.remote.RemoteTestNG.main(RemoteTestNG.java:91)
]]>
            </full-stacktrace>
          </exception> <!-- java.lang.AssertionError -->
          <reporter-output>
          </reporter-output>
        </test-method> <!-- TestCase02 -->
        <test-method signature="TestCase03()[pri:0, instance:TestNgExecuteFailedTestCases.FailedTestCaseExample@70e9c95d]" started-at="2024-08-27T14:37:11 IST" name="TestCase03" finished-at="2024-08-27T14:37:11 IST" duration-ms="2" status="PASS">
          <reporter-output>
          </reporter-output>
        </test-method> <!-- TestCase03 -->
      </class> <!-- TestNgExecuteFailedTestCases.FailedTestCaseExample -->
    </test> <!-- Test -->
  </suite> <!-- Suite -->
</testng-results>
